Workbook

Sheet 說明
A1: NEXORA GRID v3.0.0 快捷鍵對照表
A3: 這份表是什麼 | B3: 九宮格三層導覽的完整鍵位對照。資料由程式碼直接抓出（role-registry.ts），不是憑印象整理。
A4: 怎麼按 | B4: 任何畫面按 F2 開九宮格 → 打角色數字 → 打功能數字 →（有第三層的再打一次）。全程不碰滑鼠。
A5: 排列方式 | B5: 螢幕上的格子位置＝數字鍵盤的位置：上排 7 8 9／中排 4 5 6／下排 1 2 3。
A7: 0 的規則 | B7: 第一層按 0 ＝ 回首頁（離開九宮格、回工作檯）；第二層以後按 0 ＝ 回上一層。
B8: 同一顆鍵一路退到底，只要記「退一步」一件事。
A9: 角色層一律要走 | B9: 2026-08-03 執行長拍板：沒權限的角色格子變灰、不重排，⛔ 不做「單一職務跳過角色層」。
B10: 理由：跳過的話，那個人哪天多兼一個職務，全部鍵位位移一格、肌肉記憶歸零。
A12: 號碼凍結鐵則 | B12: 數字一旦配給某個功能就終身不改。新功能撿空號排後面，停用的號碼留白不回收。
B13: 顯示順序可以調，但號碼跟著功能走、不跟著位置走。上線後改號＝全公司打錯單。
A15: 狀態欄怎麼看 | B15: 已上線＝路由存在、現在就能開；建置中＝號碼定了、頁面還沒做；留白＝刻意不放東西，號碼凍結保留。
A16: 要填的欄位 | B16: 黃底儲存格是留給執行長填的（集中在「頂欄整合」那一頁）。其餘欄位由程式碼決定，改了不會影響系統。
A18: 資料來源 | B18: apps/nx-ui/src/design/navigation/role-registry.ts（2026-08-03 產出）
A19: 規格書 | B19: docs/專案/介面規格/NEXORA-介面架構-v3.0.0.md §3 §4 §5 §7
A21: 統計
A22: 第二層格子總數（9 角色 × 9 格） | B22: 81
A23: 已上線 | B23: =COUNTIF(第二層功能鍵!E:E,"已上線")
A24: 建置中 | B24: =COUNTIF(第二層功能鍵!E:E,"建置中")
A25: 留白（凍結不回收） | B25: =COUNTIF(第二層功能鍵!E:E,"留白（凍結）")
A26: 第三層子功能總數 | B26: =COUNTA(第三層子功能鍵!D:D)-1
A27: 已上線 | B27: =COUNTIF(第三層子功能鍵!E:E,"已上線")
A28: 建置中 | B28: =COUNTIF(第三層子功能鍵!E:E,"建置中")

Sheet 第一層角色鍵
A1: 第一層：F2 之後按的第一個數字＝角色
A3: 按鍵 | B3: 數字鍵盤位置 | C3: 角色 | D3: 對應部門 | E3: 已上線 | F3: 建置中 | G3: 留白 | H3: 說明
A4: F2 → 1 | B4: 下排左 | C4: 銷售作業 | D4: 業務部 | E4: =COUNTIFS(第二層功能鍵!B:B,"銷售作業",第二層功能鍵!E:E,"已上線") | F4: =COUNTIFS(第二層功能鍵!B:B,"銷售作業",第二層功能鍵!E:E,"建置中") | G4: =COUNTIFS(第二層功能鍵!B:B,"銷售作業",第二層功能鍵!E:E,"留白（凍結）") | H4: 業務一天的主線：報價→銷貨→退貨→調貨
A5: F2 → 2 | B5: 下排中 | C5: 採購作業 | D5: 採購部 | E5: =COUNTIFS(第二層功能鍵!B:B,"採購作業",第二層功能鍵!E:E,"已上線") | F5: =COUNTIFS(第二層功能鍵!B:B,"採購作業",第二層功能鍵!E:E,"建置中") | G5: =COUNTIFS(第二層功能鍵!B:B,"採購作業",第二層功能鍵!E:E,"留白（凍結）") | H5: 採購部主線
A6: F2 → 3 | B6: 下排右 | C6: 倉庫作業 | D6: 倉管部 | E6: =COUNTIFS(第二層功能鍵!B:B,"倉庫作業",第二層功能鍵!E:E,"已上線") | F6: =COUNTIFS(第二層功能鍵!B:B,"倉庫作業",第二層功能鍵!E:E,"建置中") | G6: =COUNTIFS(第二層功能鍵!B:B,"倉庫作業",第二層功能鍵!E:E,"留白（凍結）") | H6: 倉管：八格全部是作業類別，不是單據
A7: F2 → 4 | B7: 中排左 | C7: 物流作業 | D7: 倉管部 | E7: =COUNTIFS(第二層功能鍵!B:B,"物流作業",第二層功能鍵!E:E,"已上線") | F7: =COUNTIFS(第二層功能鍵!B:B,"物流作業",第二層功能鍵!E:E,"建置中") | G7: =COUNTIFS(第二層功能鍵!B:B,"物流作業",第二層功能鍵!E:E,"留白（凍結）") | H7: 外務與調度共用一個角色（功能不綁裝置）
A8: F2 → 5 | B8: 中排中 | C8: 產品作業 | D8: 產品部 | E8: =COUNTIFS(第二層功能鍵!B:B,"產品作業",第二層功能鍵!E:E,"已上線") | F8: =COUNTIFS(第二層功能鍵!B:B,"產品作業",第二層功能鍵!E:E,"建置中") | G8: =COUNTIFS(第二層功能鍵!B:B,"產品作業",第二層功能鍵!E:E,"留白（凍結）") | H8: 產品部：建檔、定價、替代料
A9: F2 → 6 | B9: 中排右 | C9: 出納作業 | D9: 財務部 | E9: =COUNTIFS(第二層功能鍵!B:B,"出納作業",第二層功能鍵!E:E,"已上線") | F9: =COUNTIFS(第二層功能鍵!B:B,"出納作業",第二層功能鍵!E:E,"建置中") | G9: =COUNTIFS(第二層功能鍵!B:B,"出納作業",第二層功能鍵!E:E,"留白（凍結）") | H9: 管錢的（與會計分開是內控要求）
A10: F2 → 7 | B10: 上排左 | C10: 會計作業 | D10: 財務部 | E10: =COUNTIFS(第二層功能鍵!B:B,"會計作業",第二層功能鍵!E:E,"已上線") | F10: =COUNTIFS(第二層功能鍵!B:B,"會計作業",第二層功能鍵!E:E,"建置中") | G10: =COUNTIFS(第二層功能鍵!B:B,"會計作業",第二層功能鍵!E:E,"留白（凍結）") | H10: 管帳的（3／6／9 由總帳軌產出）
A11: F2 → 8 | B11: 上排中 | C11: 經營作業 | D11: 總經理／董事長 | E11: =COUNTIFS(第二層功能鍵!B:B,"經營作業",第二層功能鍵!E:E,"已上線") | F11: =COUNTIFS(第二層功能鍵!B:B,"經營作業",第二層功能鍵!E:E,"建置中") | G11: =COUNTIFS(第二層功能鍵!B:B,"經營作業",第二層功能鍵!E:E,"留白（凍結）") | H11: 總經理／董事長看的
A12: F2 → 9 | B12: 上排右 | C12: 行政作業 | D12: 管理部 | E12: =COUNTIFS(第二層功能鍵!B:B,"行政作業",第二層功能鍵!E:E,"已上線") | F12: =COUNTIFS(第二層功能鍵!B:B,"行政作業",第二層功能鍵!E:E,"建置中") | G12: =COUNTIFS(第二層功能鍵!B:B,"行政作業",第二層功能鍵!E:E,"留白（凍結）") | H12: 管理部：人、事務、資產

Sheet 第二層功能鍵
A1: 第二層：角色底下的九個功能格
A3: 按鍵序列 | B3: 角色 | C3: 格號 | D3: 功能名稱 | E3: 狀態 | F3: 有第三層 | G3: 路由 | H3: 備註
A4: F2 → 1 → 1 | B4: 銷售作業 | C4: 1 | D4: 報價作業 | E4: 已上線 | F4: 有 | H4: 有第三層。客戶來電的落點；查價查貨併在裡面
A5: F2 → 1 → 2 | B5: 銷售作業 | C5: 2 | D5: 銷貨作業 | E5: 已上線 | F5: 有 | H5: 有第三層
A6: F2 → 1 → 3 | B6: 銷售作業 | C6: 3 | D6: 退貨作業 | E6: 已上線 | G6: /dashboard/sale/return
A7: F2 → 1 → 4 | B7: 銷售作業 | C7: 4 | D7: 調貨作業 | E7: 已上線 | G7: /dashboard/purchase/ti | H7: 詢價紀錄要併進來
A8: F2 → 1 → 5 | B8: 銷售作業 | C8: 5 | D8: 客戶管理 | E8: 已上線 | G8: /dashboard/master/partners/customer
A9: F2 → 1 → 6 | B9: 銷售作業 | C9: 6 | D9: 對帳查詢 | E9: 已上線 | G9: /dashboard/report/finance/ar-overview
A10: F2 → 1 → 7 | B10: 銷售作業 | C10: 7 | D10: 保固查詢 | E10: 已上線 | G10: /dashboard/sale/warranty
A11: F2 → 1 → 8 | B11: 銷售作業 | C11: 8 | D11: 銷售分析 | E11: 已上線 | G11: /dashboard/report/sales
A12: F2 → 1 → 9 | B12: 銷售作業 | C12: 9 | D12: （留白） | E12: 留白（凍結） | H12: 執行長 2026-08-01 明確留白
A13: F2 → 2 → 1 | B13: 採購作業 | C13: 1 | D13: 缺貨簿 | E13: 已上線 | G13: /dashboard/purchase/demand
A14: F2 → 2 → 2 | B14: 採購作業 | C14: 2 | D14: 採購單 | E14: 已上線 | G14: /dashboard/purchase/po
A15: F2 → 2 → 3 | B15: 採購作業 | C15: 3 | D15: 詢價作業 | E15: 已上線 | G15: /dashboard/purchase/rfq
A16: F2 → 2 → 4 | B16: 採購作業 | C16: 4 | D16: 進貨單 | E16: 已上線 | G16: /dashboard/purchase/rr
A17: F2 → 2 → 5 | B17: 採購作業 | C17: 5 | D17: 進貨退回 | E17: 已上線 | G17: /dashboard/purchase/pr
A18: F2 → 2 → 6 | B18: 採購作業 | C18: 6 | D18: 交期追蹤 | E18: 建置中 | H18: 採購真正的痛點：追未到的貨
A19: F2 → 2 → 7 | B19: 採購作業 | C19: 7 | D19: 保固求償 | E19: 已上線 | G19: /dashboard/purchase/warranty
A20: F2 → 2 → 8 | B20: 採購作業 | C20: 8 | D20: 供應商管理 | E20: 已上線 | G20: /dashboard/master/partners/supplier
A21: F2 → 2 → 9 | B21: 採購作業 | C21: 9 | D21: 採購分析 | E21: 已上線 | G21: /dashboard/report/purchase
A22: F2 → 3 → 1 | B22: 倉庫作業 | C22: 1 | D22: 入庫作業 | E22: 已上線 | F22: 有 | H22: 有第三層
A23: F2 → 3 → 2 | B23: 倉庫作業 | C23: 2 | D23: 出庫作業 | E23: 已上線 | F23: 有 | H23: 有第三層
A24: F2 → 3 → 3 | B24: 倉庫作業 | C24: 3 | D24: 調撥作業 | E24: 已上線 | F24: 有 | H24: 有第三層
A25: F2 → 3 → 4 | B25: 倉庫作業 | C25: 4 | D25: 盤點作業 | E25: 已上線 | F25: 有 | H25: 有第三層
A26: F2 → 3 → 5 | B26: 倉庫作業 | C26: 5 | D26: 重組分解 | E26: 已上線 | F26: 有 | H26: 有第三層
A27: F2 → 3 → 6 | B27: 倉庫作業 | C27: 6 | D27: 異常回報 | E27: 已上線 | F27: 有 | H27: 有第三層
A28: F2 → 3 → 7 | B28: 倉庫作業 | C28: 7 | D28: 庫位管理 | E28: 已上線 | F28: 有 | H28: 有第三層
A29: F2 → 3 → 8 | B29: 倉庫作業 | C29: 8 | D29: 倉庫分析 | E29: 已上線 | F29: 有 | H29: 有第三層
A30: F2 → 3 → 9 | B30: 倉庫作業 | C30: 9 | D30: （留白） | E30: 留白（凍結） | H30: 留白，不硬湊
A31: F2 → 4 → 1 | B31: 物流作業 | C31: 1 | D31: 今日配送 | E31: 已上線 | G31: /dashboard/delivery/dispatch
A32: F2 → 4 → 2 | B32: 物流作業 | C32: 2 | D32: 送貨單 | E32: 已上線 | G32: /dashboard/inventory/delivery
A33: F2 → 4 → 3 | B33: 物流作業 | C33: 3 | D33: 簽收回報 | E33: 已上線 | G33: /dashboard/delivery/sign
A34: F2 → 4 → 4 | B34: 物流作業 | C34: 4 | D34: 代收貨款 | E34: 建置中 | H34: 司機收現金回來要交出納：錢與帳分離
A35: F2 → 4 → 5 | B35: 物流作業 | C35: 5 | D35: 異常回報 | E35: 已上線 | G35: /dashboard/delivery/exception
A36: F2 → 4 → 6 | B36: 物流作業 | C36: 6 | D36: 退貨取回 | E36: 建置中
A37: F2 → 4 → 7 | B37: 物流作業 | C37: 7 | D37: 配送排程 | E37: 已上線 | G37: /dashboard/delivery/route
A38: F2 → 4 → 8 | B38: 物流作業 | C38: 8 | D38: 車輛管理 | E38: 建置中
A39: F2 → 4 → 9 | B39: 物流作業 | C39: 9 | D39: 物流分析 | E39: 已上線 | G39: /dashboard/report/warehouse-lead/route-efficiency
A40: F2 → 5 → 1 | B40: 產品作業 | C40: 1 | D40: 產品建檔 | E40: 已上線 | G40: /dashboard/master/parts
A41: F2 → 5 → 2 | B41: 產品作業 | C41: 2 | D41: 產品維護 | E41: 已上線 | G41: /dashboard/inventory/product-maintenance
...

Sheet 第三層子功能鍵
A1: 第三層：只有 12 個功能格有第三層，其餘兩下到位
A3: 按鍵序列 | B3: 角色 | C3: 上層功能 | D3: 子功能名稱 | E3: 狀態 | F3: 路由 | G3: 備註
A4: F2 → 1 → 1 → 1 | B4: 銷售作業 | C4: 報價作業 | D4: 建立報價 | E4: 已上線 | F4: /dashboard/sale/quote | G4: 開單殼，五段流程
A5: F2 → 1 → 1 → 2 | B5: 銷售作業 | C5: 報價作業 | D5: 報價管理 | E5: 已上線 | F5: /dashboard/sale/qt | G5: 清單→檢視殼
A6: F2 → 1 → 2 → 1 | B6: 銷售作業 | C6: 銷貨作業 | D6: 建立銷貨單 | E6: 已上線 | F6: /dashboard/sale/order | G6: 開單殼
A7: F2 → 1 → 2 → 2 | B7: 銷售作業 | C7: 銷貨作業 | D7: 銷貨管理 | E7: 已上線 | F7: /dashboard/sale/so
A8: F2 → 3 → 1 → 1 | B8: 倉庫作業 | C8: 入庫作業 | D8: 進貨驗收 | E8: 已上線 | F8: /dashboard/inventory/receiving | G8: 現場殼
A9: F2 → 3 → 1 → 2 | B9: 倉庫作業 | C9: 入庫作業 | D9: 調撥驗收 | E9: 建置中
A10: F2 → 3 → 1 → 3 | B10: 倉庫作業 | C10: 入庫作業 | D10: 銷退驗收 | E10: 建置中
A11: F2 → 3 → 2 → 1 | B11: 倉庫作業 | C11: 出庫作業 | D11: 撿貨 | E11: 已上線 | F11: /dashboard/inventory/picking | G11: 現場殼
A12: F2 → 3 → 2 → 2 | B12: 倉庫作業 | C12: 出庫作業 | D12: 包貨 | E12: 已上線 | F12: /dashboard/inventory/packing | G12: 現場殼
A13: F2 → 3 → 2 → 3 | B13: 倉庫作業 | C13: 出庫作業 | D13: 出貨 | E13: 已上線 | F13: /dashboard/inventory/ship-zones | G13: 現場殼
A14: F2 → 3 → 3 → 1 | B14: 倉庫作業 | C14: 調撥作業 | D14: 調撥單 | E14: 已上線 | F14: /dashboard/inventory/transfer
A15: F2 → 3 → 3 → 2 | B15: 倉庫作業 | C15: 調撥作業 | D15: 自動補貨設定 | E15: 已上線 | F15: /dashboard/inventory/auto-replenish
A16: F2 → 3 → 4 → 1 | B16: 倉庫作業 | C16: 盤點作業 | D16: 盤點單 | E16: 已上線 | F16: /dashboard/inventory/stock-take | G16: 現場殼
A17: F2 → 3 → 4 → 2 | B17: 倉庫作業 | C17: 盤點作業 | D17: 盤點差異表 | E17: 建置中
A18: F2 → 3 → 5 → 1 | B18: 倉庫作業 | C18: 重組分解 | D18: 重組分解單 | E18: 已上線 | F18: /dashboard/inventory/conversion
A19: F2 → 3 → 5 → 2 | B19: 倉庫作業 | C19: 重組分解 | D19: 報廢申請 | E19: 已上線 | F19: /dashboard/inventory/disposal
A20: F2 → 3 → 6 → 1 | B20: 倉庫作業 | C20: 異常回報 | D20: 誤差回報 | E20: 已上線 | F20: /dashboard/inventory/issue-report
A21: F2 → 3 → 6 → 2 | B21: 倉庫作業 | C21: 異常回報 | D21: 品質異常 | E21: 建置中
A22: F2 → 3 → 7 → 1 | B22: 倉庫作業 | C22: 庫位管理 | D22: 庫位 | E22: 已上線 | F22: /dashboard/master/location
A23: F2 → 3 → 7 → 2 | B23: 倉庫作業 | C23: 庫位管理 | D23: 貨架 | E23: 已上線 | F23: /dashboard/master/warehouse-rack
A24: F2 → 3 → 7 → 3 | B24: 倉庫作業 | C24: 庫位管理 | D24: 區域 | E24: 已上線 | F24: /dashboard/master/warehouse-zone
A25: F2 → 3 → 7 → 4 | B25: 倉庫作業 | C25: 庫位管理 | D25: 據點架構圖 | E25: 已上線 | F25: /dashboard/master/location-structure
A26: F2 → 3 → 8 → 1 | B26: 倉庫作業 | C26: 倉庫分析 | D26: 庫存報表 | E26: 已上線 | F26: /dashboard/report/inventory
A27: F2 → 3 → 8 → 2 | B27: 倉庫作業 | C27: 倉庫分析 | D27: 週轉分析 | E27: 已上線 | F27: /dashboard/report/warehouse-staff/turnover
A28: F2 → 3 → 8 → 3 | B28: 倉庫作業 | C28: 倉庫分析 | D28: 呆滯料 | E28: 已上線 | F28: /dashboard/report/warehouse-staff/dormant
A29: F2 → 5 → 7 → 1 | B29: 產品作業 | C29: 替代料管理 | D29: 通用表 | E29: 已上線 | F29: /dashboard/master/universal-group
A30: F2 → 5 → 7 → 2 | B30: 產品作業 | C30: 替代料管理 | D30: 改版表 | E30: 已上線 | F30: /dashboard/master/part-relation
A31: F2 → 5 → 7 → 3 | B31: 產品作業 | C31: 替代料管理 | D31: 適配車型 | E31: 已上線 | F31: /dashboard/master/part-model | G31: 汽配專屬，換行業整層移除
A32: F2 → 8 → 4 → 1 | B32: 經營作業 | C32: 經營報表 | D32: 損益表 | E32: 已上線 | F32: /dashboard/report/pnl
A33: F2 → 8 → 4 → 2 | B33: 經營作業 | C33: 經營報表 | D33: 營運報表 | E33: 已上線 | F33: /dashboard/report/ops
A34: F2 → 8 → 4 → 3 | B34: 經營作業 | C34: 經營報表 | D34: 部門績效 | E34: 已上線 | F34: /dashboard/report/owner/dept-perf
A35: F2 → 8 → 4 → 4 | B35: 經營作業 | C35: 經營報表 | D35: 跨模組分析 | E35: 已上線 | F35: /dashboard/report/strategy/cross-module
A36: F2 → 8 → 4 → 5 | B36: 經營作業 | C36: 經營報表 | D36: BCG 矩陣 | E36: 已上線 | F36: /dashboard/report/strategy/bcg-matrix
A37: F2 → 9 → 1 → 1 | B37: 行政作業 | C37: 人員資料 | D37: 員工資料 | E37: 已上線 | F37: /dashboard/hr/employee
A38: F2 → 9 → 1 → 2 | B38: 行政作業 | C38: 人員資料 | D38: 出勤 | E38: 已上線 | F38: /dashboard/hr/attendance
A39: F2 → 9 → 1 → 3 | B39: 行政作業 | C39: 人員資料 | D39: 請假 | E39: 已上線 | F39: /dashboard/hr/leave
A40: F2 → 9 → 1 → 4 | B40: 行政作業 | C40: 人員資料 | D40: 薪資 | E40: 已上線 | F40: /dashboard/hr/salary
A41: F2 → 9 → 8 → 1 | B41: 行政作業 | C41: 字典設定 | D41: 國家 | E41: 已上線 | F41: /dashboard/master/country
...

Sheet 頂欄整合待填
A1: 數字鍵盤整鍵複製＋頂欄收進九宮格（2026-08-03 新方向）
A2: 黃底＝請執行長填。1–9 已被角色佔滿且終身凍結，所以頂欄那四個功能只能落在數字鍵盤的其餘實體鍵上。
A4: 實體鍵 | B4: 鍵盤位置 | C4: 目前用途 | D4: 現況 | E4: 我的建議 | F4: 執行長裁示 | G4: 理由／備註
A5: F2 | B5: 功能鍵列 | C5: 開／關九宮格 | D5: 已實作 | E5: 維持 | F5: ✅ 2026-08-03 維持 | G5: 全系統唯一的全域鍵，刻意只有一個
A6: 1–9 | B6: 數字鍵盤主區 | C6: 選角色／功能／子功能 | D6: 已實作 | E6: 維持 | F6: ✅ 2026-08-03 維持 | G6: 號碼凍結，⛔ 不可挪作他用
A7: 0 | B7: 數字鍵盤下排長鍵 | C7: 第一層＝回首頁；其餘層＝回上一層 | D7: 要改 | E7: 照裁示改 | F7: ✅ 2026-08-03 拍板 | G7: 位置最好按，給最常用的「退一步」。退到底（第一層）再按就離開九宮格、回工作檯
A8: Esc | B8: 左上角 | C8: 關閉九宮格 | D8: 已實作 | E8: 維持 | F8: ✅ 2026-08-03 維持 | G8: 與 0 分工：0 退一層、Esc 直接整個關掉
A9: . | B9: 數字鍵盤右下 | C9: 資訊 | D9: 要做 | E9: 個人資訊／行事曆／佈告欄 | F9: ✅ 2026-08-03 拍板・名稱定為「資訊」 | G9: 走同一套九宮格結構＝等於第十個角色，⛔ 不另發明選單
A10: Enter | B10: 數字鍵盤右下長鍵 | C10: 確認 | D10: 要做 | E10: 確認進入目前選取的格 | F10: ✅ 2026-08-03 拍板 | G10: 滑鼠使用者用點的，鍵盤使用者用 Enter
A11: + | B11: 數字鍵盤右側 | C11: 任務／通知按鈕 | D11: 要做 | E11: 任務／通知 | F11: ✅ 2026-08-03 拍板 | G11: 待辦池頁面已存在（/dashboard/task-pool），可直接接
A12: - | B12: 數字鍵盤右側 | C12: 設定按鈕 | D12: 要做 | E12: 設定 | F12: ✅ 2026-08-03 拍板 | G12: 頂欄現有的設定鈕搬過來
A13: * | B13: 數字鍵盤右上 | C13: （未使用） | D13: 空著 | E13: （保留） | G13: 建議留白，不要一次把鍵位用完
A14: / | B14: 數字鍵盤右上 | C14: 全域搜尋 | D14: 要做 | E14: 全域搜尋 | F14: ✅ 2026-08-03 拍板 | G14: 規格已定：搜尋不做成頁面、同一個框依角色回不同答案
A15: NumLock | B15: 數字鍵盤左上 | C15: （不攔） | D15: 還給系統 | E15: 不攔 | G15: 攔了會讓整個數字鍵盤失效
A16: Backspace | B16: 主鍵盤 | C16: （未使用） | D16: 空著 | E16: （保留） | G16: 與 0 功能重複，建議不做
A18: 頂欄現有四顆按鈕（要被收進去的東西）
A19: 頂欄按鈕 | B19: 現在的狀態 | C19: 收進九宮格之後放哪 | D19: 執行長裁示
A20: 功能選單 | B20: 已實作＝F2 九宮格本體 | C20: 不動，它就是入口 | D20: ✅ 2026-08-03
A21: 待辦 | B21: 頂欄有按鈕、標示建置中 | C21: 掛 + 鍵（任務／通知） | D21: ✅ 2026-08-03 拍板
A22: 使用者 | B22: 已實作（顯示姓名／員編） | C22: 併進 . 鍵的「資訊」 | D22: ✅ 2026-08-03 拍板
A23: 設定 | B23: 已實作 | C23: 掛 - 鍵 | D23: ✅ 2026-08-03 拍板

Sheet 資訊按鈕待設計
A1: . 鍵 「資訊」（2026-08-03 執行長拍板定名）
A2: 黃底＝請執行長填。這一格走同一套九宮格結構（等於第十個角色），⛔ 不為它另外發明一種選單。
A4: 一、按鈕名稱（已定案）
A5: 候選名稱 | B5: 優點 | C5: 缺點 | D5: 執行長裁示
A6: 資訊 | B6: 涵蓋得最廣，蓋得住「公司發的」與「我自己的」兩種東西 | C6: 看不出裡面有什麼，靠格子內容補 | D6: ✅ 2026-08-03 採用
A7: 我的 | B7: 兩個字最短、最好念 | C7: 佈告欄是公司的、不是我的，名字蓋不住 | D7: 不採用
A8: 個人專區 | B8: 意思最清楚 | C8: 四個字，格子裡字會擠 | D8: 不採用
A9: 公司與我 | B9: 把「公司發布的」和「我自己的」都講到了 | C9: 不像 ERP 用語，較口語 | D9: 不採用
A11: 二、裡面放什麼（九格，號碼一樣終身凍結）
A12: 格號 | B12: 內容 | C12: 現況 | D12: 現成的東西在哪 | E12: 執行長裁示
A13: 1 | B13: 個人資訊 | C13: 頂欄已有（只顯示姓名／員編） | D13: V3TopBar 使用者鈕 | E13: ✅ 執行長已點名
A14: 2 | B14: 行事曆 | C14: 後端已有 API、前端元件在封存的舊首頁裡 | D14: HomeView（468 行，已接真實 API） | E14: ✅ 執行長已點名
A15: 3 | B15: 佈告欄 | C15: 只有「管理端」在行政作業 9-3；看的那一端要做 | D15: HomeView 公告區塊 | E15: ✅ 執行長已點名
A16: 4
A17: 5
A18: 6
A19: 7
A20: 8
A21: 9

Sheet 空號登記
A1: 留白與空號一覽（號碼凍結鐵則的登記簿）
A2: 新功能只能撿這些空號，⛔ 不可插隊擠掉既有號碼。
A4: 位置 | B4: 角色 | C4: 格號 | D4: 現況 | E4: 將來撿這個號的功能 | F4: 執行長裁示
A5: F2 → 1 → 9 | B5: 銷售作業 | C5: 9 | D5: 留白（刻意不硬湊）
A6: F2 → 3 → 9 | B6: 倉庫作業 | C6: 9 | D6: 留白（刻意不硬湊）
A7: F2 → 6 → 9 | B7: 出納作業 | C7: 9 | D7: 留白（刻意不硬湊）
A8: F2 → 8 → 8 | B8: 經營作業 | C8: 8 | D8: 留白（刻意不硬湊）
A9: F2 → 8 → 9 | B9: 經營作業 | C9: 9 | D9: 留白（刻意不硬湊）
